Workbook

Sheet tbl_sites
A1: name | B1: region | C1: description | D1: slug | E1: time_zone | F1: status
A2: CHUNGCU | B2: NGHE-AN | C2: Du an xay dung ha tang CTTV cho khu chung cu tai nghe an | D2: lab-hanoi | E2: Etc/GMT+7 | F2: active

Sheet tbl_locations
A1: name | B1: site | C1: status | D1: slug
A2: Toa_A1 | B2: CHUNGCU | C2: active | D2: toa-a1

Sheet tbl_racks
A1: name | B1: site | C1: location | D1: status | E1: u_height | F1: width
A2: HH1-RACK-B1 | B2: CHUNGCU | C2: Toa_A1 | D2: active | E2: 43 | F2: 19
A3: RACK-CA-H-1 | B3: CHUNGCU | C3: Toa_A1 | D3: active | E3: 43 | F3: 19
A4: RACK-CA-H-2 | B4: CHUNGCU | C4: Toa_A1 | D4: active | E4: 43 | F4: 19
A5: HH1-RACK-T5 | B5: CHUNGCU | C5: Toa_A1 | D5: active | E5: 43 | F5: 19
A6: HH1-RACK-T10 | B6: CHUNGCU | C6: Toa_A1 | D6: active | E6: 43 | F6: 19
A7: HH1-RACK-T15 | B7: CHUNGCU | C7: Toa_A1 | D7: active | E7: 43 | F7: 19
A8: HH1-RACK-T19 | B8: CHUNGCU | C8: Toa_A1 | D8: active | E8: 43 | F8: 19
A9: CCTV-MRACK | B9: CHUNGCU | C9: Toa_A1 | D9: active | E9: 43 | F9: 19

Sheet tbl_vlan
A1: vid | B1: name | C1: status | D1: description
A2: 1 | B2: SETUP | C2: active | D2: Setup_HeThong
A3: 10 | B3: MGMT | C3: active | D3: Quan tri thiet bi mang
A4: 20 | B4: CAMERAS | C4: active | D4: He thong cam hanh lang
A5: 30 | B5: WiFi | C5: active | D5: Wifi nội bộ

Sheet tbl_prefixes
A1: prefix | B1: vlan | C1: status
A2: 10.0.1.0/24 | B2: 1 | C2: active
A3: 10.0.10.0/24 | B3: 10 | C3: active
A4: 10.0.20.0/24 | B4: 20 | C4: active
A5: 10.0.30.0/24 | B5: 30 | C5: active

Sheet tbl_device-roles
A1: name | B1: color | C1: slug
A2: ACC_SW | B2: 9e9e9e | C2: acc_sw
A3: CORE_SW | B3: 9e9e9e | C3: core_sw

Sheet tbl_manufacturers
A1: name | B1: description | C1: slug
A2: Cisco | B2: Nha phan phoi cisco | C2: cisco

Sheet tbl_device-types
A1: model | B1: manufacturer | C1: u_height | D1: slug
A2: TEST_C1 | B2: Cisco | C2: 1 | D2: TEST_C1

Sheet tbl_devices
A1: name | B1: device_type | C1: status | D1: location | E1: site | F1: role | G1: manufacturer | H1: cf_device_number | I1: rack
A2: =I2&"-"&B2&"-"&F2&"-"&H2 -> CCTV-MRACK-TEST_C1-CORE_SW-01 | B2: TEST_C1 | C2: active | D2: Toa_A1 | E2: CHUNGCU | F2: CORE_SW | G2: Cisco | H2: 01 | I2: CCTV-MRACK
A3: =I3&"-"&B3&"-"&F3&"-"&H3 -> HH1-RACK-B1-TEST_C1-ACC_SW-01 | B3: TEST_C1 | C3: active | D3: Toa_A1 | E3: CHUNGCU | F3: ACC_SW | G3: Cisco | H3: 01 | I3: HH1-RACK-B1
A4: =I4&"-"&B4&"-"&F4&"-"&H4 -> RACK-CA-H-1-TEST_C1-ACC_SW-01 | B4: TEST_C1 | C4: active | D4: Toa_A1 | E4: CHUNGCU | F4: ACC_SW | G4: Cisco | H4: 01 | I4: RACK-CA-H-1
A5: =I5&"-"&B5&"-"&F5&"-"&H5 -> RACK-CA-H-1-TEST_C1-ACC_SW-02 | B5: TEST_C1 | C5: active | D5: Toa_A1 | E5: CHUNGCU | F5: ACC_SW | G5: Cisco | H5: 02 | I5: RACK-CA-H-1
A6: =I6&"-"&B6&"-"&F6&"-"&H6 -> RACK-CA-H-2-TEST_C1-ACC_SW-01 | B6: TEST_C1 | C6: active | D6: Toa_A1 | E6: CHUNGCU | F6: ACC_SW | G6: Cisco | H6: 01 | I6: RACK-CA-H-2
A7: =I7&"-"&B7&"-"&F7&"-"&H7 -> HH1-RACK-T5-TEST_C1-ACC_SW-01 | B7: TEST_C1 | C7: active | D7: Toa_A1 | E7: CHUNGCU | F7: ACC_SW | G7: Cisco | H7: 01 | I7: HH1-RACK-T5
A8: =I8&"-"&B8&"-"&F8&"-"&H8 -> HH1-RACK-T10-TEST_C1-ACC_SW-01 | B8: TEST_C1 | C8: active | D8: Toa_A1 | E8: CHUNGCU | F8: ACC_SW | G8: Cisco | H8: 01 | I8: HH1-RACK-T10
A9: =I9&"-"&B9&"-"&F9&"-"&H9 -> HH1-RACK-T19-TEST_C1-ACC_SW-01 | B9: TEST_C1 | C9: active | D9: Toa_A1 | E9: CHUNGCU | F9: ACC_SW | G9: Cisco | H9: 01 | I9: HH1-RACK-T19
A10: =I10&"-"&B10&"-"&F10&"-"&H10 -> CCTV-MRACK-TEST_C1-ACC_SW-02 | B10: TEST_C1 | C10: active | D10: Toa_A1 | E10: CHUNGCU | F10: ACC_SW | G10: Cisco | H10: 02 | I10: CCTV-MRACK
A11: =I11&"-"&B11&"-"&F11&"-"&H11 -> HH1-RACK-T15-TEST_C1-ACC_SW-01 | B11: TEST_C1 | C11: active | D11: Toa_A1 | E11: CHUNGCU | F11: ACC_SW | G11: Cisco | H11: 01 | I11: HH1-RACK-T15

Sheet tbl_interfaces
A1: name | B1: device | C1: enabled | D1: type | E1: description | F1: mode | G1: untagged_vlan | H1: tagged_vlans | I1: cf_port_role
A2: Et0/0 | B2: =tbl_devices!A3 -> HH1-RACK-B1-TEST_C1-ACC_SW-01 | C2: TRUE | D2: 100base-tx | E2: Uplink to Distribution/Core Switch | F2: tagged | H2: 1,10,20 | I2: UPLINK
A3: Et0/1 | B3: =tbl_devices!A3 -> HH1-RACK-B1-TEST_C1-ACC_SW-01 | C3: TRUE | D3: 100base-tx | E3: Uplink to Distribution/Core Switch | F3: tagged | H3: 1,10,20 | I3: UPLINK
A4: Et0/2 | B4: =tbl_devices!A3 -> HH1-RACK-B1-TEST_C1-ACC_SW-01 | C4: TRUE | D4: 100base-tx | E4: CCTV Camera | F4: access | G4: 20 | I4: CAMERA
A5: Et0/3 | B5: =tbl_devices!A3 -> HH1-RACK-B1-TEST_C1-ACC_SW-01 | C5: TRUE | D5: 100base-tx | E5: CCTV Camera | F5: access | G5: 20 | I5: CAMERA
A6: Et1/0 | B6: =tbl_devices!A3 -> HH1-RACK-B1-TEST_C1-ACC_SW-01 | C6: TRUE | D6: 100base-tx | E6: CCTV Camera | F6: access | G6: 20 | I6: CAMERA
A7: Et1/1 | B7: =tbl_devices!A3 -> HH1-RACK-B1-TEST_C1-ACC_SW-01 | C7: TRUE | D7: 100base-tx | E7: CCTV Camera | F7: access | G7: 20 | I7: CAMERA
A8: Et1/2 | B8: =tbl_devices!A3 -> HH1-RACK-B1-TEST_C1-ACC_SW-01 | C8: TRUE | D8: 100base-tx | E8: CCTV Camera | F8: access | G8: 20 | I8: CAMERA
A9: Et1/3 | B9: =tbl_devices!A3 -> HH1-RACK-B1-TEST_C1-ACC_SW-01 | C9: TRUE | D9: 100base-tx | E9: CCTV Camera | F9: access | G9: 20 | I9: CAMERA
A10: Et2/0 | B10: =tbl_devices!A3 -> HH1-RACK-B1-TEST_C1-ACC_SW-01 | C10: TRUE | D10: 100base-tx | E10: CCTV Camera | F10: access | G10: 20 | I10: CAMERA
A11: Et2/1 | B11: =tbl_devices!A3 -> HH1-RACK-B1-TEST_C1-ACC_SW-01 | C11: TRUE | D11: 100base-tx | E11: CCTV Camera | F11: access | G11: 20 | I11: CAMERA
A12: Et2/2 | B12: =tbl_devices!A3 -> HH1-RACK-B1-TEST_C1-ACC_SW-01 | C12: TRUE | D12: 100base-tx | E12: CCTV Camera | F12: access | G12: 20 | I12: CAMERA
A13: Et2/3 | B13: =tbl_devices!A3 -> HH1-RACK-B1-TEST_C1-ACC_SW-01 | C13: TRUE | D13: 100base-tx | E13: CCTV Camera | F13: access | G13: 20 | I13: CAMERA
A14: Et3/0 | B14: =tbl_devices!A3 -> HH1-RACK-B1-TEST_C1-ACC_SW-01 | C14: TRUE | D14: 100base-tx | E14: CCTV Camera | F14: access | G14: 20 | I14: CAMERA
A15: Et3/1 | B15: =tbl_devices!A3 -> HH1-RACK-B1-TEST_C1-ACC_SW-01 | C15: TRUE | D15: 100base-tx | E15: CCTV Camera | F15: access | G15: 20 | I15: CAMERA
A16: Et3/2 | B16: =tbl_devices!A3 -> HH1-RACK-B1-TEST_C1-ACC_SW-01 | C16: TRUE | D16: 100base-tx | E16: CCTV Camera | F16: access | G16: 20 | I16: CAMERA
A17: Et3/3 | B17: =tbl_devices!A3 -> HH1-RACK-B1-TEST_C1-ACC_SW-01 | C17: TRUE | D17: 100base-tx | E17: CCTV Camera | F17: access | G17: 20 | I17: CAMERA
A18: VLAN10 | B18: =tbl_devices!A3 -> HH1-RACK-B1-TEST_C1-ACC_SW-01 | C18: TRUE | D18: virtual
A19: VLAN1 | B19: =tbl_devices!A3 -> HH1-RACK-B1-TEST_C1-ACC_SW-01 | C19: TRUE | D19: virtual
A20: Et0/0 | B20: =tbl_devices!A4 -> RACK-CA-H-1-TEST_C1-ACC_SW-01 | C20: TRUE | D20: 100base-tx | E20: Uplink to Distribution/Core Switch | F20: tagged | H20: 1,10,20 | I20: UPLINK
A21: Et0/1 | B21: =tbl_devices!A4 -> RACK-CA-H-1-TEST_C1-ACC_SW-01 | C21: TRUE | D21: 100base-tx | E21: Uplink to Distribution/Core Switch | F21: tagged | H21: 1,10,20 | I21: UPLINK
A22: Et0/2 | B22: =tbl_devices!A4 -> RACK-CA-H-1-TEST_C1-ACC_SW-01 | C22: TRUE | D22: 100base-tx | E22: Downlink to Distribution/Core Switch | F22: tagged | H22: 1,10,20 | I22: UPLINK
A23: Et0/3 | B23: =tbl_devices!A4 -> RACK-CA-H-1-TEST_C1-ACC_SW-01 | C23: TRUE | D23: 100base-tx | E23: Downlink to Distribution/Core Switch | F23: tagged | H23: 1,10,20 | I23: UPLINK
A24: Et1/0 | B24: =tbl_devices!A4 -> RACK-CA-H-1-TEST_C1-ACC_SW-01 | C24: TRUE | D24: 100base-tx | E24: CCTV Camera | F24: access | G24: 20 | I24: CAMERA
A25: Et1/1 | B25: =tbl_devices!A4 -> RACK-CA-H-1-TEST_C1-ACC_SW-01 | C25: TRUE | D25: 100base-tx | E25: CCTV Camera | F25: access | G25: 20 | I25: CAMERA
A26: Et1/2 | B26: =tbl_devices!A4 -> RACK-CA-H-1-TEST_C1-ACC_SW-01 | C26: TRUE | D26: 100base-tx | E26: CCTV Camera | F26: access | G26: 20 | I26: CAMERA
A27: Et1/3 | B27: =tbl_devices!A4 -> RACK-CA-H-1-TEST_C1-ACC_SW-01 | C27: TRUE | D27: 100base-tx | E27: CCTV Camera | F27: access | G27: 20 | I27: CAMERA
A28: Et2/0 | B28: =tbl_devices!A4 -> RACK-CA-H-1-TEST_C1-ACC_SW-01 | C28: TRUE | D28: 100base-tx | E28: CCTV Camera | F28: access | G28: 20 | I28: CAMERA
A29: Et2/1 | B29: =tbl_devices!A4 -> RACK-CA-H-1-TEST_C1-ACC_SW-01 | C29: TRUE | D29: 100base-tx | E29: CCTV Camera | F29: access | G29: 20 | I29: CAMERA
A30: Et2/2 | B30: =tbl_devices!A4 -> RACK-CA-H-1-TEST_C1-ACC_SW-01 | C30: TRUE | D30: 100base-tx | E30: CCTV Camera | F30: access | G30: 20 | I30: CAMERA
A31: Et2/3 | B31: =tbl_devices!A4 -> RACK-CA-H-1-TEST_C1-ACC_SW-01 | C31: TRUE | D31: 100base-tx | E31: CCTV Camera | F31: access | G31: 20 | I31: CAMERA
A32: Et3/0 | B32: =tbl_devices!A4 -> RACK-CA-H-1-TEST_C1-ACC_SW-01 | C32: TRUE | D32: 100base-tx | E32: CCTV Camera | F32: access | G32: 20 | I32: CAMERA
A33: Et3/1 | B33: =tbl_devices!A4 -> RACK-CA-H-1-TEST_C1-ACC_SW-01 | C33: TRUE | D33: 100base-tx | E33: CCTV Camera | F33: access | G33: 20 | I33: CAMERA
A34: Et3/2 | B34: =tbl_devices!A4 -> RACK-CA-H-1-TEST_C1-ACC_SW-01 | C34: TRUE | D34: 100base-tx | E34: CCTV Camera | F34: access | G34: 20 | I34: CAMERA
A35: Et3/3 | B35: =tbl_devices!A4 -> RACK-CA-H-1-TEST_C1-ACC_SW-01 | C35: TRUE | D35: 100base-tx | E35: CCTV Camera | F35: access | G35: 20 | I35: CAMERA
A36: VLAN10 | B36: =tbl_devices!A4 -> RACK-CA-H-1-TEST_C1-ACC_SW-01 | C36: TRUE | D36: virtual
A37: VLAN1 | B37: =tbl_devices!A4 -> RACK-CA-H-1-TEST_C1-ACC_SW-01 | C37: TRUE | D37: virtual
A38: Et0/0 | B38: =tbl_devices!A5 -> RACK-CA-H-1-TEST_C1-ACC_SW-02 | C38: TRUE | D38: 100base-tx | E38: Uplink to Distribution/Core Switch | F38: tagged | H38: 1,10,20 | I38: UPLINK
A39: Et0/1 | B39: =tbl_devices!A5 -> RACK-CA-H-1-TEST_C1-ACC_SW-02 | C39: TRUE | D39: 100base-tx | E39: Uplink to Distribution/Core Switch | F39: tagged | H39: 1,10,20 | I39: UPLINK
A40: Et0/2 | B40: =tbl_devices!A5 -> RACK-CA-H-1-TEST_C1-ACC_SW-02 | C40: TRUE | D40: 100base-tx | E40: CCTV Camera | F40: access | G40: 20 | I40: CAMERA
...

Sheet tbl_IP-addresses
A1: address | B1: status | C1: interface | D1: device | E1: is_primary
A2: 192.168.80.10/24 | B2: active | C2: VLAN1 | D2: =tbl_devices!A2 -> CCTV-MRACK-TEST_C1-CORE_SW-01 | E2: TRUE
A3: 192.168.80.11/24 | B3: active | C3: VLAN1 | D3: =tbl_devices!A3 -> HH1-RACK-B1-TEST_C1-ACC_SW-01 | E3: TRUE
A4: 192.168.80.12/24 | B4: active | C4: VLAN1 | D4: =tbl_devices!A4 -> RACK-CA-H-1-TEST_C1-ACC_SW-01 | E4: TRUE
A5: 192.168.80.13/24 | B5: active | C5: VLAN1 | D5: =tbl_devices!A5 -> RACK-CA-H-1-TEST_C1-ACC_SW-02 | E5: TRUE
A6: 192.168.80.14/24 | B6: active | C6: VLAN1 | D6: =tbl_devices!A6 -> RACK-CA-H-2-TEST_C1-ACC_SW-01 | E6: TRUE
A7: 192.168.80.15/24 | B7: active | C7: VLAN1 | D7: =tbl_devices!A7 -> HH1-RACK-T5-TEST_C1-ACC_SW-01 | E7: TRUE
A8: 192.168.80.16/24 | B8: active | C8: VLAN1 | D8: =tbl_devices!A8 -> HH1-RACK-T10-TEST_C1-ACC_SW-01 | E8: TRUE
A9: 192.168.80.17/24 | B9: active | C9: VLAN1 | D9: =tbl_devices!A9 -> HH1-RACK-T19-TEST_C1-ACC_SW-01 | E9: TRUE
A10: 192.168.80.18/24 | B10: active | C10: VLAN1 | D10: =tbl_devices!A10 -> CCTV-MRACK-TEST_C1-ACC_SW-02 | E10: TRUE
A11: 192.168.80.19/24 | B11: active | C11: VLAN1 | D11: =tbl_devices!A11 -> HH1-RACK-T15-TEST_C1-ACC_SW-01 | E11: TRUE
A12: 10.0.5.10/24 | B12: active | C12: VLAN10 | D12: =tbl_devices!A2 -> CCTV-MRACK-TEST_C1-CORE_SW-01 | E12: TRUE
A13: 10.0.5.11/24 | B13: active | C13: VLAN10 | D13: =tbl_devices!A3 -> HH1-RACK-B1-TEST_C1-ACC_SW-01 | E13: TRUE
A14: 10.0.5.12/24 | B14: active | C14: VLAN10 | D14: =tbl_devices!A4 -> RACK-CA-H-1-TEST_C1-ACC_SW-01 | E14: TRUE
A15: 10.0.5.13/24 | B15: active | C15: VLAN10 | D15: =tbl_devices!A5 -> RACK-CA-H-1-TEST_C1-ACC_SW-02 | E15: TRUE
A16: 10.0.5.14/24 | B16: active | C16: VLAN10 | D16: =tbl_devices!A6 -> RACK-CA-H-2-TEST_C1-ACC_SW-01 | E16: TRUE
A17: 10.0.5.15/24 | B17: active | C17: VLAN10 | D17: =tbl_devices!A7 -> HH1-RACK-T5-TEST_C1-ACC_SW-01 | E17: TRUE
A18: 10.0.5.16/24 | B18: active | C18: VLAN10 | D18: =tbl_devices!A8 -> HH1-RACK-T10-TEST_C1-ACC_SW-01 | E18: TRUE
A19: 10.0.5.17/24 | B19: active | C19: VLAN10 | D19: =tbl_devices!A9 -> HH1-RACK-T19-TEST_C1-ACC_SW-01 | E19: TRUE
A20: 10.0.5.18/24 | B20: active | C20: VLAN10 | D20: =tbl_devices!A10 -> CCTV-MRACK-TEST_C1-ACC_SW-02 | E20: TRUE
A21: 10.0.5.19/24 | B21: active | C21: VLAN10 | D21: =tbl_devices!A11 -> HH1-RACK-T15-TEST_C1-ACC_SW-01 | E21: TRUE

Sheet tbl_netbox-cables
A1: side_a_type | B1: side_a_device | C1: side_a_name | D1: side_b_type | E1: side_b_device | F1: side_b_name | G1: status | H1: description
A2: dcim.interface | B2: =tbl_devices!A2 -> CCTV-MRACK-TEST_C1-CORE_SW-01 | C2: Et0/0 | D2: dcim.interface | E2: =tbl_devices!A3 -> HH1-RACK-B1-TEST_C1-ACC_SW-01 | F2: Et0/0 | G2: connected | H2: ="DOWNLINK | "&E2&" | "&F2&"" -> DOWNLINK | HH1-RACK-B1-TEST_C1-ACC_SW-01 | Et0/0
A3: dcim.interface | B3: =tbl_devices!A2 -> CCTV-MRACK-TEST_C1-CORE_SW-01 | C3: Et0/1 | D3: dcim.interface | E3: =tbl_devices!A3 -> HH1-RACK-B1-TEST_C1-ACC_SW-01 | F3: Et0/1 | G3: connected | H3: ="DOWNLINK | "&E3&" | "&F3&"" -> DOWNLINK | HH1-RACK-B1-TEST_C1-ACC_SW-01 | Et0/1
A4: dcim.interface | B4: =tbl_devices!A2 -> CCTV-MRACK-TEST_C1-CORE_SW-01 | C4: Et0/2 | D4: dcim.interface | E4: =tbl_devices!A4 -> RACK-CA-H-1-TEST_C1-ACC_SW-01 | F4: Et0/0 | G4: connected | H4: ="DOWNLINK | "&E4&" | "&F4&"" -> DOWNLINK | RACK-CA-H-1-TEST_C1-ACC_SW-01 | Et0/0
A5: dcim.interface | B5: =tbl_devices!A2 -> CCTV-MRACK-TEST_C1-CORE_SW-01 | C5: Et0/3 | D5: dcim.interface | E5: =tbl_devices!A4 -> RACK-CA-H-1-TEST_C1-ACC_SW-01 | F5: Et0/1 | G5: connected | H5: ="DOWNLINK | "&E5&" | "&F5&"" -> DOWNLINK | RACK-CA-H-1-TEST_C1-ACC_SW-01 | Et0/1
A6: dcim.interface | B6: =tbl_devices!A2 -> CCTV-MRACK-TEST_C1-CORE_SW-01 | C6: Et1/0 | D6: dcim.interface | E6: =tbl_devices!A6 -> RACK-CA-H-2-TEST_C1-ACC_SW-01 | F6: Et0/0 | G6: connected | H6: ="DOWNLINK | "&E6&" | "&F6&"" -> DOWNLINK | RACK-CA-H-2-TEST_C1-ACC_SW-01 | Et0/0
A7: dcim.interface | B7: =tbl_devices!A2 -> CCTV-MRACK-TEST_C1-CORE_SW-01 | C7: Et1/1 | D7: dcim.interface | E7: =tbl_devices!A6 -> RACK-CA-H-2-TEST_C1-ACC_SW-01 | F7: Et0/1 | G7: connected | H7: ="DOWNLINK | "&E7&" | "&F7&"" -> DOWNLINK | RACK-CA-H-2-TEST_C1-ACC_SW-01 | Et0/1
A8: dcim.interface | B8: =tbl_devices!A2 -> CCTV-MRACK-TEST_C1-CORE_SW-01 | C8: Et1/2 | D8: dcim.interface | E8: =tbl_devices!A7 -> HH1-RACK-T5-TEST_C1-ACC_SW-01 | F8: Et0/0 | G8: connected | H8: ="DOWNLINK | "&E8&" | "&F8&"" -> DOWNLINK | HH1-RACK-T5-TEST_C1-ACC_SW-01 | Et0/0
A9: dcim.interface | B9: =tbl_devices!A2 -> CCTV-MRACK-TEST_C1-CORE_SW-01 | C9: Et1/3 | D9: dcim.interface | E9: =tbl_devices!A7 -> HH1-RACK-T5-TEST_C1-ACC_SW-01 | F9: Et0/1 | G9: connected | H9: ="DOWNLINK | "&E9&" | "&F9&"" -> DOWNLINK | HH1-RACK-T5-TEST_C1-ACC_SW-01 | Et0/1
A10: dcim.interface | B10: =tbl_devices!A2 -> CCTV-MRACK-TEST_C1-CORE_SW-01 | C10: Et2/2 | D10: dcim.interface | E10: =tbl_devices!A8 -> HH1-RACK-T10-TEST_C1-ACC_SW-01 | F10: Et0/0 | G10: connected | H10: ="DOWNLINK | "&E10&" | "&F10&"" -> DOWNLINK | HH1-RACK-T10-TEST_C1-ACC_SW-01 | Et0/0
A11: dcim.interface | B11: =tbl_devices!A2 -> CCTV-MRACK-TEST_C1-CORE_SW-01 | C11: Et2/3 | D11: dcim.interface | E11: =tbl_devices!A8 -> HH1-RACK-T10-TEST_C1-ACC_SW-01 | F11: Et0/1 | G11: connected | H11: ="DOWNLINK | "&E11&" | "&F11&"" -> DOWNLINK | HH1-RACK-T10-TEST_C1-ACC_SW-01 | Et0/1
A12: dcim.interface | B12: =tbl_devices!A2 -> CCTV-MRACK-TEST_C1-CORE_SW-01 | C12: Et3/0 | D12: dcim.interface | E12: =tbl_devices!A9 -> HH1-RACK-T19-TEST_C1-ACC_SW-01 | F12: Et0/0 | G12: connected | H12: ="DOWNLINK | "&E12&" | "&F12&"" -> DOWNLINK | HH1-RACK-T19-TEST_C1-ACC_SW-01 | Et0/0
A13: dcim.interface | B13: =tbl_devices!A2 -> CCTV-MRACK-TEST_C1-CORE_SW-01 | C13: Et3/1 | D13: dcim.interface | E13: =tbl_devices!A9 -> HH1-RACK-T19-TEST_C1-ACC_SW-01 | F13: Et0/1 | G13: connected | H13: ="DOWNLINK | "&E13&" | "&F13&"" -> DOWNLINK | HH1-RACK-T19-TEST_C1-ACC_SW-01 | Et0/1
A14: dcim.interface | B14: =tbl_devices!A2 -> CCTV-MRACK-TEST_C1-CORE_SW-01 | C14: Et3/2 | D14: dcim.interface | E14: =tbl_devices!A9 -> HH1-RACK-T19-TEST_C1-ACC_SW-01 | F14: Et0/0 | G14: connected | H14: ="DOWNLINK | "&E14&" | "&F14&"" -> DOWNLINK | HH1-RACK-T19-TEST_C1-ACC_SW-01 | Et0/0
A15: dcim.interface | B15: =tbl_devices!A2 -> CCTV-MRACK-TEST_C1-CORE_SW-01 | C15: Et3/3 | D15: dcim.interface | E15: =tbl_devices!A9 -> HH1-RACK-T19-TEST_C1-ACC_SW-01 | F15: Et0/1 | G15: connected | H15: ="DOWNLINK | "&E15&" | "&F15&"" -> DOWNLINK | HH1-RACK-T19-TEST_C1-ACC_SW-01 | Et0/1
A16: dcim.interface | B16: =tbl_devices!A4 -> RACK-CA-H-1-TEST_C1-ACC_SW-01 | C16: Et0/2 | D16: dcim.interface | E16: =tbl_devices!A11 -> HH1-RACK-T15-TEST_C1-ACC_SW-01 | F16: Et0/0 | G16: connected | H16: ="DOWNLINK | "&E16&" | "&F16&"" -> DOWNLINK | HH1-RACK-T15-TEST_C1-ACC_SW-01 | Et0/0
A17: dcim.interface | B17: =tbl_devices!A4 -> RACK-CA-H-1-TEST_C1-ACC_SW-01 | C17: Et0/3 | D17: dcim.interface | E17: =tbl_devices!A11 -> HH1-RACK-T15-TEST_C1-ACC_SW-01 | F17: Et0/1 | G17: connected | H17: ="DOWNLINK | "&E17&" | "&F17&"" -> DOWNLINK | HH1-RACK-T15-TEST_C1-ACC_SW-01 | Et0/1
A18: dcim.interface | B18: =tbl_devices!A2 -> CCTV-MRACK-TEST_C1-CORE_SW-01 | C18: Et2/0 | D18: dcim.interface | E18: =tbl_devices!A10 -> CCTV-MRACK-TEST_C1-ACC_SW-02 | F18: Et0/0 | G18: connected | H18: ="DOWNLINK | "&E18&" | "&F18&"" -> DOWNLINK | CCTV-MRACK-TEST_C1-ACC_SW-02 | Et0/0
A19: dcim.interface | B19: =tbl_devices!A2 -> CCTV-MRACK-TEST_C1-CORE_SW-01 | C19: Et2/1 | D19: dcim.interface | E19: =tbl_devices!A10 -> CCTV-MRACK-TEST_C1-ACC_SW-02 | F19: Et0/1 | G19: connected | H19: ="DOWNLINK | "&E19&" | "&F19&"" -> DOWNLINK | CCTV-MRACK-TEST_C1-ACC_SW-02 | Et0/1
